ERROR    fs_live_stat_parser.py[LINE:16 2020-07-31 19:11][get_html] Error receive html https://www.flashscore.com/match/fR9xLykq
Traceback (most recent call last):
  File "/home/max/Projects/football-stat-scraper/stat_scraper/fs_live_stat_parser.py", line 9, in get_html
    driver = get_driver()
  File "/home/max/Projects/football-stat-scraper/stat_scraper/init_driver.py", line 10, in get_driver
    driver = webdriver.Chrome(options=chrome_options,
  File "/home/max/.local/lib/python3.8/site-packages/selenium/webdriver/chrome/webdriver.py", line 73, in __init__
    self.service.start()
  File "/home/max/.local/lib/python3.8/site-packages/selenium/webdriver/common/service.py", line 98, in start
    self.assert_process_still_running()
  File "/home/max/.local/lib/python3.8/site-packages/selenium/webdriver/common/service.py", line 109, in assert_process_still_running
    raise WebDriverException(
selenium.common.exceptions.WebDriverException: Message: Service ./chromedriver unexpectedly exited. Status code was: 1

ERROR    fs_live_stat_parser.py[LINE:16 2020-07-31 19:11][get_html] Error receive html https://www.flashscore.com/match/hrg6SJd9
Traceback (most recent call last):
  File "/home/max/Projects/football-stat-scraper/stat_scraper/fs_live_stat_parser.py", line 9, in get_html
    driver = get_driver()
  File "/home/max/Projects/football-stat-scraper/stat_scraper/init_driver.py", line 10, in get_driver
    driver = webdriver.Chrome(options=chrome_options,
  File "/home/max/.local/lib/python3.8/site-packages/selenium/webdriver/chrome/webdriver.py", line 73, in __init__
    self.service.start()
  File "/home/max/.local/lib/python3.8/site-packages/selenium/webdriver/common/service.py", line 98, in start
    self.assert_process_still_running()
  File "/home/max/.local/lib/python3.8/site-packages/selenium/webdriver/common/service.py", line 109, in assert_process_still_running
    raise WebDriverException(
selenium.common.exceptions.WebDriverException: Message: Service ./chromedriver unexpectedly exited. Status code was: 1

ERROR    fs_live_stat_parser.py[LINE:16 2020-07-31 19:11][get_html] Error receive html https://www.flashscore.com/match/fPrqF9Mh
Traceback (most recent call last):
  File "/home/max/Projects/football-stat-scraper/stat_scraper/fs_live_stat_parser.py", line 9, in get_html
    driver = get_driver()
  File "/home/max/Projects/football-stat-scraper/stat_scraper/init_driver.py", line 10, in get_driver
    driver = webdriver.Chrome(options=chrome_options,
  File "/home/max/.local/lib/python3.8/site-packages/selenium/webdriver/chrome/webdriver.py", line 73, in __init__
    self.service.start()
  File "/home/max/.local/lib/python3.8/site-packages/selenium/webdriver/common/service.py", line 98, in start
    self.assert_process_still_running()
  File "/home/max/.local/lib/python3.8/site-packages/selenium/webdriver/common/service.py", line 109, in assert_process_still_running
    raise WebDriverException(
selenium.common.exceptions.WebDriverException: Message: Service ./chromedriver unexpectedly exited. Status code was: 1

ERROR    speed_run_test.py[LINE:45 2020-07-31 19:11][run_parse] ERROR RUN PARSE ON URL https://www.flashscore.com/match/fPrqF9Mh
Traceback (most recent call last):
  File "/home/max/Projects/football-stat-scraper/tests/speed_run_test.py", line 41, in run_parse
    summary_stat.update(get_live_stat(url))
  File "/home/max/Projects/football-stat-scraper/stat_scraper/fs_live_stat_parser.py", line 96, in get_live_stat
    live_stat.update(get_main_stat(url))
  File "/home/max/Projects/football-stat-scraper/stat_scraper/fs_live_stat_parser.py", line 67, in get_main_stat
    html = get_html(url)
  File "/home/max/Projects/football-stat-scraper/stat_scraper/fs_live_stat_parser.py", line 17, in get_html
    return html
UnboundLocalError: local variable 'html' referenced before assignment
ERROR    fs_live_stat_parser.py[LINE:16 2020-07-31 19:11][get_html] Error receive html https://www.flashscore.com/match/2eVaBRLH
Traceback (most recent call last):
  File "/usr/lib/python3/dist-packages/urllib3/connection.py", line 156, in _new_conn
    conn = connection.create_connection(
  File "/usr/lib/python3/dist-packages/urllib3/util/connection.py", line 84, in create_connection
    raise err
  File "/usr/lib/python3/dist-packages/urllib3/util/connection.py", line 74, in create_connection
    sock.connect(sa)
ConnectionRefusedError: [Errno 111] Connection refused

During handling of the above exception, another exception occurred:

Traceback (most recent call last):
  File "/usr/lib/python3/dist-packages/urllib3/connectionpool.py", line 665, in urlopen
    httplib_response = self._make_request(
  File "/usr/lib/python3/dist-packages/urllib3/connectionpool.py", line 387, in _make_request
    conn.request(method, url, **httplib_request_kw)
  File "/usr/lib/python3.8/http/client.py", line 1240, in request
    self._send_request(method, url, body, headers, encode_chunked)
  File "/usr/lib/python3.8/http/client.py", line 1286, in _send_request
    self.endheaders(body, encode_chunked=encode_chunked)
  File "/usr/lib/python3.8/http/client.py", line 1235, in endheaders
    self._send_output(message_body, encode_chunked=encode_chunked)
  File "/usr/lib/python3.8/http/client.py", line 1006, in _send_output
    self.send(msg)
  File "/usr/lib/python3.8/http/client.py", line 946, in send
    self.connect()
  File "/usr/lib/python3/dist-packages/urllib3/connection.py", line 184, in connect
    conn = self._new_conn()
  File "/usr/lib/python3/dist-packages/urllib3/connection.py", line 168, in _new_conn
    raise NewConnectionError(
urllib3.exceptions.NewConnectionError: <urllib3.connection.HTTPConnection object at 0x7fb88cf7f340>: Failed to establish a new connection: [Errno 111] Connection refused

During handling of the above exception, another exception occurred:

Traceback (most recent call last):
  File "/home/max/Projects/football-stat-scraper/stat_scraper/fs_live_stat_parser.py", line 9, in get_html
    driver = get_driver()
  File "/home/max/Projects/football-stat-scraper/stat_scraper/init_driver.py", line 10, in get_driver
    driver = webdriver.Chrome(options=chrome_options,
  File "/home/max/.local/lib/python3.8/site-packages/selenium/webdriver/chrome/webdriver.py", line 76, in __init__
    RemoteWebDriver.__init__(
  File "/home/max/.local/lib/python3.8/site-packages/selenium/webdriver/remote/webdriver.py", line 157, in __init__
    self.start_session(capabilities, browser_profile)
  File "/home/max/.local/lib/python3.8/site-packages/selenium/webdriver/remote/webdriver.py", line 252, in start_session
    response = self.execute(Command.NEW_SESSION, parameters)
  File "/home/max/.local/lib/python3.8/site-packages/selenium/webdriver/remote/webdriver.py", line 319, in execute
    response = self.command_executor.execute(driver_command, params)
  File "/home/max/.local/lib/python3.8/site-packages/selenium/webdriver/remote/remote_connection.py", line 374, in execute
    return self._request(command_info[0], url, body=data)
  File "/home/max/.local/lib/python3.8/site-packages/selenium/webdriver/remote/remote_connection.py", line 397, in _request
    resp = self._conn.request(method, url, body=body, headers=headers)
  File "/usr/lib/python3/dist-packages/urllib3/request.py", line 79, in request
    return self.request_encode_body(
  File "/usr/lib/python3/dist-packages/urllib3/request.py", line 171, in request_encode_body
    return self.urlopen(method, url, **extra_kw)
  File "/usr/lib/python3/dist-packages/urllib3/poolmanager.py", line 330, in urlopen
    response = conn.urlopen(method, u.request_uri, **kw)
  File "/usr/lib/python3/dist-packages/urllib3/connectionpool.py", line 747, in urlopen
    return self.urlopen(
  File "/usr/lib/python3/dist-packages/urllib3/connectionpool.py", line 747, in urlopen
    return self.urlopen(
  File "/usr/lib/python3/dist-packages/urllib3/connectionpool.py", line 747, in urlopen
    return self.urlopen(
  File "/usr/lib/python3/dist-packages/urllib3/connectionpool.py", line 719, in urlopen
    retries = retries.increment(
  File "/usr/lib/python3/dist-packages/urllib3/util/retry.py", line 436, in increment
    raise MaxRetryError(_pool, url, error or ResponseError(cause))
urllib3.exceptions.MaxRetryError: HTTPConnectionPool(host='localhost', port=50807): Max retries exceeded with url: /session (Caused by NewConnectionError('<urllib3.connection.HTTPConnection object at 0x7fb88cf7f340>: Failed to establish a new connection: [Errno 111] Connection refused'))
ERROR    speed_run_test.py[LINE:45 2020-07-31 19:11][run_parse] ERROR RUN PARSE ON URL https://www.flashscore.com/match/2eVaBRLH
Traceback (most recent call last):
  File "/home/max/Projects/football-stat-scraper/tests/speed_run_test.py", line 41, in run_parse
    summary_stat.update(get_live_stat(url))
  File "/home/max/Projects/football-stat-scraper/stat_scraper/fs_live_stat_parser.py", line 96, in get_live_stat
    live_stat.update(get_main_stat(url))
  File "/home/max/Projects/football-stat-scraper/stat_scraper/fs_live_stat_parser.py", line 67, in get_main_stat
    html = get_html(url)
  File "/home/max/Projects/football-stat-scraper/stat_scraper/fs_live_stat_parser.py", line 17, in get_html
    return html
UnboundLocalError: local variable 'html' referenced before assignment
ERROR    fs_live_stat_parser.py[LINE:16 2020-07-31 19:11][get_html] Error receive html https://www.flashscore.com/match/xlYmETya
Traceback (most recent call last):
  File "/usr/lib/python3/dist-packages/urllib3/connectionpool.py", line 665, in urlopen
    httplib_response = self._make_request(
  File "/usr/lib/python3/dist-packages/urllib3/connectionpool.py", line 421, in _make_request
    six.raise_from(e, None)
  File "<string>", line 3, in raise_from
  File "/usr/lib/python3/dist-packages/urllib3/connectionpool.py", line 416, in _make_request
    httplib_response = conn.getresponse()
  File "/usr/lib/python3.8/http/client.py", line 1332, in getresponse
    response.begin()
  File "/usr/lib/python3.8/http/client.py", line 303, in begin
    version, status, reason = self._read_status()
  File "/usr/lib/python3.8/http/client.py", line 264, in _read_status
    line = str(self.fp.readline(_MAXLINE + 1), "iso-8859-1")
  File "/usr/lib/python3.8/socket.py", line 669, in readinto
    return self._sock.recv_into(b)
ConnectionResetError: [Errno 104] Connection reset by peer

During handling of the above exception, another exception occurred:

Traceback (most recent call last):
  File "/home/max/Projects/football-stat-scraper/stat_scraper/fs_live_stat_parser.py", line 9, in get_html
    driver = get_driver()
  File "/home/max/Projects/football-stat-scraper/stat_scraper/init_driver.py", line 10, in get_driver
    driver = webdriver.Chrome(options=chrome_options,
  File "/home/max/.local/lib/python3.8/site-packages/selenium/webdriver/chrome/webdriver.py", line 76, in __init__
    RemoteWebDriver.__init__(
  File "/home/max/.local/lib/python3.8/site-packages/selenium/webdriver/remote/webdriver.py", line 157, in __init__
    self.start_session(capabilities, browser_profile)
  File "/home/max/.local/lib/python3.8/site-packages/selenium/webdriver/remote/webdriver.py", line 252, in start_session
    response = self.execute(Command.NEW_SESSION, parameters)
  File "/home/max/.local/lib/python3.8/site-packages/selenium/webdriver/remote/webdriver.py", line 319, in execute
    response = self.command_executor.execute(driver_command, params)
  File "/home/max/.local/lib/python3.8/site-packages/selenium/webdriver/remote/remote_connection.py", line 374, in execute
    return self._request(command_info[0], url, body=data)
  File "/home/max/.local/lib/python3.8/site-packages/selenium/webdriver/remote/remote_connection.py", line 397, in _request
    resp = self._conn.request(method, url, body=body, headers=headers)
  File "/usr/lib/python3/dist-packages/urllib3/request.py", line 79, in request
    return self.request_encode_body(
  File "/usr/lib/python3/dist-packages/urllib3/request.py", line 171, in request_encode_body
    return self.urlopen(method, url, **extra_kw)
  File "/usr/lib/python3/dist-packages/urllib3/poolmanager.py", line 330, in urlopen
    response = conn.urlopen(method, u.request_uri, **kw)
  File "/usr/lib/python3/dist-packages/urllib3/connectionpool.py", line 719, in urlopen
    retries = retries.increment(
  File "/usr/lib/python3/dist-packages/urllib3/util/retry.py", line 400, in increment
    raise six.reraise(type(error), error, _stacktrace)
  File "/usr/lib/python3/dist-packages/six.py", line 702, in reraise
    raise value.with_traceback(tb)
  File "/usr/lib/python3/dist-packages/urllib3/connectionpool.py", line 665, in urlopen
    httplib_response = self._make_request(
  File "/usr/lib/python3/dist-packages/urllib3/connectionpool.py", line 421, in _make_request
    six.raise_from(e, None)
  File "<string>", line 3, in raise_from
  File "/usr/lib/python3/dist-packages/urllib3/connectionpool.py", line 416, in _make_request
    httplib_response = conn.getresponse()
  File "/usr/lib/python3.8/http/client.py", line 1332, in getresponse
    response.begin()
  File "/usr/lib/python3.8/http/client.py", line 303, in begin
    version, status, reason = self._read_status()
  File "/usr/lib/python3.8/http/client.py", line 264, in _read_status
    line = str(self.fp.readline(_MAXLINE + 1), "iso-8859-1")
  File "/usr/lib/python3.8/socket.py", line 669, in readinto
    return self._sock.recv_into(b)
urllib3.exceptions.ProtocolError: ('Connection aborted.', ConnectionResetError(104, 'Connection reset by peer'))
ERROR    speed_run_test.py[LINE:45 2020-07-31 19:11][run_parse] ERROR RUN PARSE ON URL https://www.flashscore.com/match/fR9xLykq
Traceback (most recent call last):
  File "/home/max/Projects/football-stat-scraper/tests/speed_run_test.py", line 41, in run_parse
    summary_stat.update(get_live_stat(url))
  File "/home/max/Projects/football-stat-scraper/stat_scraper/fs_live_stat_parser.py", line 96, in get_live_stat
    live_stat.update(get_main_stat(url))
  File "/home/max/Projects/football-stat-scraper/stat_scraper/fs_live_stat_parser.py", line 67, in get_main_stat
    html = get_html(url)
  File "/home/max/Projects/football-stat-scraper/stat_scraper/fs_live_stat_parser.py", line 17, in get_html
    return html
UnboundLocalError: local variable 'html' referenced before assignment
ERROR    speed_run_test.py[LINE:45 2020-07-31 19:11][run_parse] ERROR RUN PARSE ON URL https://www.flashscore.com/match/hrg6SJd9
Traceback (most recent call last):
  File "/home/max/Projects/football-stat-scraper/tests/speed_run_test.py", line 41, in run_parse
    summary_stat.update(get_live_stat(url))
  File "/home/max/Projects/football-stat-scraper/stat_scraper/fs_live_stat_parser.py", line 96, in get_live_stat
    live_stat.update(get_main_stat(url))
  File "/home/max/Projects/football-stat-scraper/stat_scraper/fs_live_stat_parser.py", line 67, in get_main_stat
    html = get_html(url)
  File "/home/max/Projects/football-stat-scraper/stat_scraper/fs_live_stat_parser.py", line 17, in get_html
    return html
UnboundLocalError: local variable 'html' referenced before assignment
ERROR    fs_live_stat_parser.py[LINE:16 2020-07-31 19:11][get_html] Error receive html https://www.flashscore.com/match/ljzKGMcc
Traceback (most recent call last):
  File "/usr/lib/python3/dist-packages/urllib3/connectionpool.py", line 665, in urlopen
    httplib_response = self._make_request(
  File "/usr/lib/python3/dist-packages/urllib3/connectionpool.py", line 421, in _make_request
    six.raise_from(e, None)
  File "<string>", line 3, in raise_from
  File "/usr/lib/python3/dist-packages/urllib3/connectionpool.py", line 416, in _make_request
    httplib_response = conn.getresponse()
  File "/usr/lib/python3.8/http/client.py", line 1332, in getresponse
    response.begin()
  File "/usr/lib/python3.8/http/client.py", line 303, in begin
    version, status, reason = self._read_status()
  File "/usr/lib/python3.8/http/client.py", line 264, in _read_status
    line = str(self.fp.readline(_MAXLINE + 1), "iso-8859-1")
  File "/usr/lib/python3.8/socket.py", line 669, in readinto
    return self._sock.recv_into(b)
ConnectionResetError: [Errno 104] Connection reset by peer

During handling of the above exception, another exception occurred:

Traceback (most recent call last):
  File "/home/max/Projects/football-stat-scraper/stat_scraper/fs_live_stat_parser.py", line 9, in get_html
    driver = get_driver()
  File "/home/max/Projects/football-stat-scraper/stat_scraper/init_driver.py", line 10, in get_driver
    driver = webdriver.Chrome(options=chrome_options,
  File "/home/max/.local/lib/python3.8/site-packages/selenium/webdriver/chrome/webdriver.py", line 76, in __init__
    RemoteWebDriver.__init__(
  File "/home/max/.local/lib/python3.8/site-packages/selenium/webdriver/remote/webdriver.py", line 157, in __init__
    self.start_session(capabilities, browser_profile)
  File "/home/max/.local/lib/python3.8/site-packages/selenium/webdriver/remote/webdriver.py", line 252, in start_session
    response = self.execute(Command.NEW_SESSION, parameters)
  File "/home/max/.local/lib/python3.8/site-packages/selenium/webdriver/remote/webdriver.py", line 319, in execute
    response = self.command_executor.execute(driver_command, params)
  File "/home/max/.local/lib/python3.8/site-packages/selenium/webdriver/remote/remote_connection.py", line 374, in execute
    return self._request(command_info[0], url, body=data)
  File "/home/max/.local/lib/python3.8/site-packages/selenium/webdriver/remote/remote_connection.py", line 397, in _request
    resp = self._conn.request(method, url, body=body, headers=headers)
  File "/usr/lib/python3/dist-packages/urllib3/request.py", line 79, in request
    return self.request_encode_body(
  File "/usr/lib/python3/dist-packages/urllib3/request.py", line 171, in request_encode_body
    return self.urlopen(method, url, **extra_kw)
  File "/usr/lib/python3/dist-packages/urllib3/poolmanager.py", line 330, in urlopen
    response = conn.urlopen(method, u.request_uri, **kw)
  File "/usr/lib/python3/dist-packages/urllib3/connectionpool.py", line 719, in urlopen
    retries = retries.increment(
  File "/usr/lib/python3/dist-packages/urllib3/util/retry.py", line 400, in increment
    raise six.reraise(type(error), error, _stacktrace)
  File "/usr/lib/python3/dist-packages/six.py", line 702, in reraise
    raise value.with_traceback(tb)
  File "/usr/lib/python3/dist-packages/urllib3/connectionpool.py", line 665, in urlopen
    httplib_response = self._make_request(
  File "/usr/lib/python3/dist-packages/urllib3/connectionpool.py", line 421, in _make_request
    six.raise_from(e, None)
  File "<string>", line 3, in raise_from
  File "/usr/lib/python3/dist-packages/urllib3/connectionpool.py", line 416, in _make_request
    httplib_response = conn.getresponse()
  File "/usr/lib/python3.8/http/client.py", line 1332, in getresponse
    response.begin()
  File "/usr/lib/python3.8/http/client.py", line 303, in begin
    version, status, reason = self._read_status()
  File "/usr/lib/python3.8/http/client.py", line 264, in _read_status
    line = str(self.fp.readline(_MAXLINE + 1), "iso-8859-1")
  File "/usr/lib/python3.8/socket.py", line 669, in readinto
    return self._sock.recv_into(b)
urllib3.exceptions.ProtocolError: ('Connection aborted.', ConnectionResetError(104, 'Connection reset by peer'))
ERROR    speed_run_test.py[LINE:45 2020-07-31 19:11][run_parse] ERROR RUN PARSE ON URL https://www.flashscore.com/match/xlYmETya
Traceback (most recent call last):
  File "/home/max/Projects/football-stat-scraper/tests/speed_run_test.py", line 41, in run_parse
    summary_stat.update(get_live_stat(url))
  File "/home/max/Projects/football-stat-scraper/stat_scraper/fs_live_stat_parser.py", line 96, in get_live_stat
    live_stat.update(get_main_stat(url))
  File "/home/max/Projects/football-stat-scraper/stat_scraper/fs_live_stat_parser.py", line 67, in get_main_stat
    html = get_html(url)
  File "/home/max/Projects/football-stat-scraper/stat_scraper/fs_live_stat_parser.py", line 17, in get_html
    return html
UnboundLocalError: local variable 'html' referenced before assignment
ERROR    speed_run_test.py[LINE:45 2020-07-31 19:11][run_parse] ERROR RUN PARSE ON URL https://www.flashscore.com/match/ljzKGMcc
Traceback (most recent call last):
  File "/home/max/Projects/football-stat-scraper/tests/speed_run_test.py", line 41, in run_parse
    summary_stat.update(get_live_stat(url))
  File "/home/max/Projects/football-stat-scraper/stat_scraper/fs_live_stat_parser.py", line 96, in get_live_stat
    live_stat.update(get_main_stat(url))
  File "/home/max/Projects/football-stat-scraper/stat_scraper/fs_live_stat_parser.py", line 67, in get_main_stat
    html = get_html(url)
  File "/home/max/Projects/football-stat-scraper/stat_scraper/fs_live_stat_parser.py", line 17, in get_html
    return html
UnboundLocalError: local variable 'html' referenced before assignment
ERROR    fs_live_stat_parser.py[LINE:16 2020-07-31 19:11][get_html] Error receive html https://www.flashscore.com/match/O4WeC76B
Traceback (most recent call last):
  File "/usr/lib/python3/dist-packages/urllib3/connectionpool.py", line 665, in urlopen
    httplib_response = self._make_request(
  File "/usr/lib/python3/dist-packages/urllib3/connectionpool.py", line 421, in _make_request
    six.raise_from(e, None)
  File "<string>", line 3, in raise_from
  File "/usr/lib/python3/dist-packages/urllib3/connectionpool.py", line 416, in _make_request
    httplib_response = conn.getresponse()
  File "/usr/lib/python3.8/http/client.py", line 1332, in getresponse
    response.begin()
  File "/usr/lib/python3.8/http/client.py", line 303, in begin
    version, status, reason = self._read_status()
  File "/usr/lib/python3.8/http/client.py", line 264, in _read_status
    line = str(self.fp.readline(_MAXLINE + 1), "iso-8859-1")
  File "/usr/lib/python3.8/socket.py", line 669, in readinto
    return self._sock.recv_into(b)
ConnectionResetError: [Errno 104] Connection reset by peer

During handling of the above exception, another exception occurred:

Traceback (most recent call last):
  File "/home/max/Projects/football-stat-scraper/stat_scraper/fs_live_stat_parser.py", line 9, in get_html
    driver = get_driver()
  File "/home/max/Projects/football-stat-scraper/stat_scraper/init_driver.py", line 10, in get_driver
    driver = webdriver.Chrome(options=chrome_options,
  File "/home/max/.local/lib/python3.8/site-packages/selenium/webdriver/chrome/webdriver.py", line 76, in __init__
    RemoteWebDriver.__init__(
  File "/home/max/.local/lib/python3.8/site-packages/selenium/webdriver/remote/webdriver.py", line 157, in __init__
    self.start_session(capabilities, browser_profile)
  File "/home/max/.local/lib/python3.8/site-packages/selenium/webdriver/remote/webdriver.py", line 252, in start_session
    response = self.execute(Command.NEW_SESSION, parameters)
  File "/home/max/.local/lib/python3.8/site-packages/selenium/webdriver/remote/webdriver.py", line 319, in execute
    response = self.command_executor.execute(driver_command, params)
  File "/home/max/.local/lib/python3.8/site-packages/selenium/webdriver/remote/remote_connection.py", line 374, in execute
    return self._request(command_info[0], url, body=data)
  File "/home/max/.local/lib/python3.8/site-packages/selenium/webdriver/remote/remote_connection.py", line 397, in _request
    resp = self._conn.request(method, url, body=body, headers=headers)
  File "/usr/lib/python3/dist-packages/urllib3/request.py", line 79, in request
    return self.request_encode_body(
  File "/usr/lib/python3/dist-packages/urllib3/request.py", line 171, in request_encode_body
    return self.urlopen(method, url, **extra_kw)
  File "/usr/lib/python3/dist-packages/urllib3/poolmanager.py", line 330, in urlopen
    response = conn.urlopen(method, u.request_uri, **kw)
  File "/usr/lib/python3/dist-packages/urllib3/connectionpool.py", line 719, in urlopen
    retries = retries.increment(
  File "/usr/lib/python3/dist-packages/urllib3/util/retry.py", line 400, in increment
    raise six.reraise(type(error), error, _stacktrace)
  File "/usr/lib/python3/dist-packages/six.py", line 702, in reraise
    raise value.with_traceback(tb)
  File "/usr/lib/python3/dist-packages/urllib3/connectionpool.py", line 665, in urlopen
    httplib_response = self._make_request(
  File "/usr/lib/python3/dist-packages/urllib3/connectionpool.py", line 421, in _make_request
    six.raise_from(e, None)
  File "<string>", line 3, in raise_from
  File "/usr/lib/python3/dist-packages/urllib3/connectionpool.py", line 416, in _make_request
    httplib_response = conn.getresponse()
  File "/usr/lib/python3.8/http/client.py", line 1332, in getresponse
    response.begin()
  File "/usr/lib/python3.8/http/client.py", line 303, in begin
    version, status, reason = self._read_status()
  File "/usr/lib/python3.8/http/client.py", line 264, in _read_status
    line = str(self.fp.readline(_MAXLINE + 1), "iso-8859-1")
  File "/usr/lib/python3.8/socket.py", line 669, in readinto
    return self._sock.recv_into(b)
urllib3.exceptions.ProtocolError: ('Connection aborted.', ConnectionResetError(104, 'Connection reset by peer'))
ERROR    speed_run_test.py[LINE:45 2020-07-31 19:11][run_parse] ERROR RUN PARSE ON URL https://www.flashscore.com/match/O4WeC76B
Traceback (most recent call last):
  File "/home/max/Projects/football-stat-scraper/tests/speed_run_test.py", line 41, in run_parse
    summary_stat.update(get_live_stat(url))
  File "/home/max/Projects/football-stat-scraper/stat_scraper/fs_live_stat_parser.py", line 96, in get_live_stat
    live_stat.update(get_main_stat(url))
  File "/home/max/Projects/football-stat-scraper/stat_scraper/fs_live_stat_parser.py", line 67, in get_main_stat
    html = get_html(url)
  File "/home/max/Projects/football-stat-scraper/stat_scraper/fs_live_stat_parser.py", line 17, in get_html
    return html
UnboundLocalError: local variable 'html' referenced before assignment
ERROR    fs_live_stat_parser.py[LINE:16 2020-07-31 19:11][get_html] Error receive html https://www.flashscore.com/match/hrHCG1t0
Traceback (most recent call last):
  File "/usr/lib/python3/dist-packages/urllib3/connectionpool.py", line 665, in urlopen
    httplib_response = self._make_request(
  File "/usr/lib/python3/dist-packages/urllib3/connectionpool.py", line 421, in _make_request
    six.raise_from(e, None)
  File "<string>", line 3, in raise_from
  File "/usr/lib/python3/dist-packages/urllib3/connectionpool.py", line 416, in _make_request
    httplib_response = conn.getresponse()
  File "/usr/lib/python3.8/http/client.py", line 1332, in getresponse
    response.begin()
  File "/usr/lib/python3.8/http/client.py", line 303, in begin
    version, status, reason = self._read_status()
  File "/usr/lib/python3.8/http/client.py", line 264, in _read_status
    line = str(self.fp.readline(_MAXLINE + 1), "iso-8859-1")
  File "/usr/lib/python3.8/socket.py", line 669, in readinto
    return self._sock.recv_into(b)
ConnectionResetError: [Errno 104] Connection reset by peer

During handling of the above exception, another exception occurred:

Traceback (most recent call last):
  File "/home/max/Projects/football-stat-scraper/stat_scraper/fs_live_stat_parser.py", line 9, in get_html
    driver = get_driver()
  File "/home/max/Projects/football-stat-scraper/stat_scraper/init_driver.py", line 10, in get_driver
    driver = webdriver.Chrome(options=chrome_options,
  File "/home/max/.local/lib/python3.8/site-packages/selenium/webdriver/chrome/webdriver.py", line 76, in __init__
    RemoteWebDriver.__init__(
  File "/home/max/.local/lib/python3.8/site-packages/selenium/webdriver/remote/webdriver.py", line 157, in __init__
    self.start_session(capabilities, browser_profile)
  File "/home/max/.local/lib/python3.8/site-packages/selenium/webdriver/remote/webdriver.py", line 252, in start_session
    response = self.execute(Command.NEW_SESSION, parameters)
  File "/home/max/.local/lib/python3.8/site-packages/selenium/webdriver/remote/webdriver.py", line 319, in execute
    response = self.command_executor.execute(driver_command, params)
  File "/home/max/.local/lib/python3.8/site-packages/selenium/webdriver/remote/remote_connection.py", line 374, in execute
    return self._request(command_info[0], url, body=data)
  File "/home/max/.local/lib/python3.8/site-packages/selenium/webdriver/remote/remote_connection.py", line 397, in _request
    resp = self._conn.request(method, url, body=body, headers=headers)
  File "/usr/lib/python3/dist-packages/urllib3/request.py", line 79, in request
    return self.request_encode_body(
  File "/usr/lib/python3/dist-packages/urllib3/request.py", line 171, in request_encode_body
    return self.urlopen(method, url, **extra_kw)
  File "/usr/lib/python3/dist-packages/urllib3/poolmanager.py", line 330, in urlopen
    response = conn.urlopen(method, u.request_uri, **kw)
  File "/usr/lib/python3/dist-packages/urllib3/connectionpool.py", line 719, in urlopen
    retries = retries.increment(
  File "/usr/lib/python3/dist-packages/urllib3/util/retry.py", line 400, in increment
    raise six.reraise(type(error), error, _stacktrace)
  File "/usr/lib/python3/dist-packages/six.py", line 702, in reraise
    raise value.with_traceback(tb)
  File "/usr/lib/python3/dist-packages/urllib3/connectionpool.py", line 665, in urlopen
    httplib_response = self._make_request(
  File "/usr/lib/python3/dist-packages/urllib3/connectionpool.py", line 421, in _make_request
    six.raise_from(e, None)
  File "<string>", line 3, in raise_from
  File "/usr/lib/python3/dist-packages/urllib3/connectionpool.py", line 416, in _make_request
    httplib_response = conn.getresponse()
  File "/usr/lib/python3.8/http/client.py", line 1332, in getresponse
    response.begin()
  File "/usr/lib/python3.8/http/client.py", line 303, in begin
    version, status, reason = self._read_status()
  File "/usr/lib/python3.8/http/client.py", line 264, in _read_status
    line = str(self.fp.readline(_MAXLINE + 1), "iso-8859-1")
  File "/usr/lib/python3.8/socket.py", line 669, in readinto
    return self._sock.recv_into(b)
urllib3.exceptions.ProtocolError: ('Connection aborted.', ConnectionResetError(104, 'Connection reset by peer'))
ERROR    speed_run_test.py[LINE:45 2020-07-31 19:11][run_parse] ERROR RUN PARSE ON URL https://www.flashscore.com/match/hrHCG1t0
Traceback (most recent call last):
  File "/home/max/Projects/football-stat-scraper/tests/speed_run_test.py", line 41, in run_parse
    summary_stat.update(get_live_stat(url))
  File "/home/max/Projects/football-stat-scraper/stat_scraper/fs_live_stat_parser.py", line 96, in get_live_stat
    live_stat.update(get_main_stat(url))
  File "/home/max/Projects/football-stat-scraper/stat_scraper/fs_live_stat_parser.py", line 67, in get_main_stat
    html = get_html(url)
  File "/home/max/Projects/football-stat-scraper/stat_scraper/fs_live_stat_parser.py", line 17, in get_html
    return html
UnboundLocalError: local variable 'html' referenced before assignment
ERROR    fs_live_stat_parser.py[LINE:16 2020-07-31 19:11][get_html] Error receive html https://www.flashscore.com/match/8UDtKe4k
Traceback (most recent call last):
  File "/usr/lib/python3/dist-packages/urllib3/connectionpool.py", line 665, in urlopen
    httplib_response = self._make_request(
  File "/usr/lib/python3/dist-packages/urllib3/connectionpool.py", line 421, in _make_request
    six.raise_from(e, None)
  File "<string>", line 3, in raise_from
  File "/usr/lib/python3/dist-packages/urllib3/connectionpool.py", line 416, in _make_request
    httplib_response = conn.getresponse()
  File "/usr/lib/python3.8/http/client.py", line 1332, in getresponse
    response.begin()
  File "/usr/lib/python3.8/http/client.py", line 303, in begin
    version, status, reason = self._read_status()
  File "/usr/lib/python3.8/http/client.py", line 264, in _read_status
    line = str(self.fp.readline(_MAXLINE + 1), "iso-8859-1")
  File "/usr/lib/python3.8/socket.py", line 669, in readinto
    return self._sock.recv_into(b)
ConnectionResetError: [Errno 104] Connection reset by peer

During handling of the above exception, another exception occurred:

Traceback (most recent call last):
  File "/home/max/Projects/football-stat-scraper/stat_scraper/fs_live_stat_parser.py", line 9, in get_html
    driver = get_driver()
  File "/home/max/Projects/football-stat-scraper/stat_scraper/init_driver.py", line 10, in get_driver
    driver = webdriver.Chrome(options=chrome_options,
  File "/home/max/.local/lib/python3.8/site-packages/selenium/webdriver/chrome/webdriver.py", line 76, in __init__
    RemoteWebDriver.__init__(
  File "/home/max/.local/lib/python3.8/site-packages/selenium/webdriver/remote/webdriver.py", line 157, in __init__
    self.start_session(capabilities, browser_profile)
  File "/home/max/.local/lib/python3.8/site-packages/selenium/webdriver/remote/webdriver.py", line 252, in start_session
    response = self.execute(Command.NEW_SESSION, parameters)
  File "/home/max/.local/lib/python3.8/site-packages/selenium/webdriver/remote/webdriver.py", line 319, in execute
    response = self.command_executor.execute(driver_command, params)
  File "/home/max/.local/lib/python3.8/site-packages/selenium/webdriver/remote/remote_connection.py", line 374, in execute
    return self._request(command_info[0], url, body=data)
  File "/home/max/.local/lib/python3.8/site-packages/selenium/webdriver/remote/remote_connection.py", line 397, in _request
    resp = self._conn.request(method, url, body=body, headers=headers)
  File "/usr/lib/python3/dist-packages/urllib3/request.py", line 79, in request
    return self.request_encode_body(
  File "/usr/lib/python3/dist-packages/urllib3/request.py", line 171, in request_encode_body
    return self.urlopen(method, url, **extra_kw)
  File "/usr/lib/python3/dist-packages/urllib3/poolmanager.py", line 330, in urlopen
    response = conn.urlopen(method, u.request_uri, **kw)
  File "/usr/lib/python3/dist-packages/urllib3/connectionpool.py", line 719, in urlopen
    retries = retries.increment(
  File "/usr/lib/python3/dist-packages/urllib3/util/retry.py", line 400, in increment
    raise six.reraise(type(error), error, _stacktrace)
  File "/usr/lib/python3/dist-packages/six.py", line 702, in reraise
    raise value.with_traceback(tb)
  File "/usr/lib/python3/dist-packages/urllib3/connectionpool.py", line 665, in urlopen
    httplib_response = self._make_request(
  File "/usr/lib/python3/dist-packages/urllib3/connectionpool.py", line 421, in _make_request
    six.raise_from(e, None)
  File "<string>", line 3, in raise_from
  File "/usr/lib/python3/dist-packages/urllib3/connectionpool.py", line 416, in _make_request
    httplib_response = conn.getresponse()
  File "/usr/lib/python3.8/http/client.py", line 1332, in getresponse
    response.begin()
  File "/usr/lib/python3.8/http/client.py", line 303, in begin
    version, status, reason = self._read_status()
  File "/usr/lib/python3.8/http/client.py", line 264, in _read_status
    line = str(self.fp.readline(_MAXLINE + 1), "iso-8859-1")
  File "/usr/lib/python3.8/socket.py", line 669, in readinto
    return self._sock.recv_into(b)
urllib3.exceptions.ProtocolError: ('Connection aborted.', ConnectionResetError(104, 'Connection reset by peer'))
ERROR    speed_run_test.py[LINE:45 2020-07-31 19:11][run_parse] ERROR RUN PARSE ON URL https://www.flashscore.com/match/8UDtKe4k
Traceback (most recent call last):
  File "/home/max/Projects/football-stat-scraper/tests/speed_run_test.py", line 41, in run_parse
    summary_stat.update(get_live_stat(url))
  File "/home/max/Projects/football-stat-scraper/stat_scraper/fs_live_stat_parser.py", line 96, in get_live_stat
    live_stat.update(get_main_stat(url))
  File "/home/max/Projects/football-stat-scraper/stat_scraper/fs_live_stat_parser.py", line 67, in get_main_stat
    html = get_html(url)
  File "/home/max/Projects/football-stat-scraper/stat_scraper/fs_live_stat_parser.py", line 17, in get_html
    return html
UnboundLocalError: local variable 'html' referenced before assignment
ERROR    fs_live_stat_parser.py[LINE:16 2020-07-31 19:11][get_html] Error receive html https://www.flashscore.com/match/YwMuCbCS
Traceback (most recent call last):
  File "/home/max/Projects/football-stat-scraper/stat_scraper/fs_live_stat_parser.py", line 9, in get_html
    driver = get_driver()
  File "/home/max/Projects/football-stat-scraper/stat_scraper/init_driver.py", line 10, in get_driver
    driver = webdriver.Chrome(options=chrome_options,
  File "/home/max/.local/lib/python3.8/site-packages/selenium/webdriver/chrome/webdriver.py", line 73, in __init__
    self.service.start()
  File "/home/max/.local/lib/python3.8/site-packages/selenium/webdriver/common/service.py", line 98, in start
    self.assert_process_still_running()
  File "/home/max/.local/lib/python3.8/site-packages/selenium/webdriver/common/service.py", line 109, in assert_process_still_running
    raise WebDriverException(
selenium.common.exceptions.WebDriverException: Message: Service ./chromedriver unexpectedly exited. Status code was: 1

ERROR    speed_run_test.py[LINE:45 2020-07-31 19:11][run_parse] ERROR RUN PARSE ON URL https://www.flashscore.com/match/YwMuCbCS
Traceback (most recent call last):
  File "/home/max/Projects/football-stat-scraper/tests/speed_run_test.py", line 41, in run_parse
    summary_stat.update(get_live_stat(url))
  File "/home/max/Projects/football-stat-scraper/stat_scraper/fs_live_stat_parser.py", line 96, in get_live_stat
    live_stat.update(get_main_stat(url))
  File "/home/max/Projects/football-stat-scraper/stat_scraper/fs_live_stat_parser.py", line 67, in get_main_stat
    html = get_html(url)
  File "/home/max/Projects/football-stat-scraper/stat_scraper/fs_live_stat_parser.py", line 17, in get_html
    return html
UnboundLocalError: local variable 'html' referenced before assignment
ERROR    fs_live_stat_parser.py[LINE:16 2020-07-31 19:11][get_html] Error receive html https://www.flashscore.com/match/SEOODaQI
Traceback (most recent call last):
  File "/home/max/Projects/football-stat-scraper/stat_scraper/fs_live_stat_parser.py", line 9, in get_html
    driver = get_driver()
  File "/home/max/Projects/football-stat-scraper/stat_scraper/init_driver.py", line 10, in get_driver
    driver = webdriver.Chrome(options=chrome_options,
  File "/home/max/.local/lib/python3.8/site-packages/selenium/webdriver/chrome/webdriver.py", line 73, in __init__
    self.service.start()
  File "/home/max/.local/lib/python3.8/site-packages/selenium/webdriver/common/service.py", line 98, in start
    self.assert_process_still_running()
  File "/home/max/.local/lib/python3.8/site-packages/selenium/webdriver/common/service.py", line 109, in assert_process_still_running
    raise WebDriverException(
selenium.common.exceptions.WebDriverException: Message: Service ./chromedriver unexpectedly exited. Status code was: 1

ERROR    speed_run_test.py[LINE:45 2020-07-31 19:11][run_parse] ERROR RUN PARSE ON URL https://www.flashscore.com/match/SEOODaQI
Traceback (most recent call last):
  File "/home/max/Projects/football-stat-scraper/tests/speed_run_test.py", line 41, in run_parse
    summary_stat.update(get_live_stat(url))
  File "/home/max/Projects/football-stat-scraper/stat_scraper/fs_live_stat_parser.py", line 96, in get_live_stat
    live_stat.update(get_main_stat(url))
  File "/home/max/Projects/football-stat-scraper/stat_scraper/fs_live_stat_parser.py", line 67, in get_main_stat
    html = get_html(url)
  File "/home/max/Projects/football-stat-scraper/stat_scraper/fs_live_stat_parser.py", line 17, in get_html
    return html
UnboundLocalError: local variable 'html' referenced before assignment
ERROR    fs_past_stat_parser.py[LINE:93 2020-07-31 19:15][get_more_events] Button show more events not found url {url}
Traceback (most recent call last):
  File "/home/max/Projects/football-stat-scraper/stat_scraper/fs_past_stat_parser.py", line 91, in get_more_events
    more_event_btn.click()
  File "/home/max/.local/lib/python3.8/site-packages/selenium/webdriver/remote/webelement.py", line 80, in click
    self._execute(Command.CLICK_ELEMENT)
  File "/home/max/.local/lib/python3.8/site-packages/selenium/webdriver/remote/webelement.py", line 633, in _execute
    return self._parent.execute(command, params)
  File "/home/max/.local/lib/python3.8/site-packages/selenium/webdriver/remote/webdriver.py", line 321, in execute
    self.error_handler.check_response(response)
  File "/home/max/.local/lib/python3.8/site-packages/selenium/webdriver/remote/errorhandler.py", line 242, in check_response
    raise exception_class(message, screen, stacktrace)
selenium.common.exceptions.StaleElementReferenceException: Message: stale element reference: element is not attached to the page document
  (Session info: headless chrome=84.0.4147.89)

ERROR    fs_past_stat_parser.py[LINE:93 2020-07-31 19:15][get_more_events] Button show more events not found url {url}
Traceback (most recent call last):
  File "/home/max/Projects/football-stat-scraper/stat_scraper/fs_past_stat_parser.py", line 91, in get_more_events
    more_event_btn.click()
  File "/home/max/.local/lib/python3.8/site-packages/selenium/webdriver/remote/webelement.py", line 80, in click
    self._execute(Command.CLICK_ELEMENT)
  File "/home/max/.local/lib/python3.8/site-packages/selenium/webdriver/remote/webelement.py", line 633, in _execute
    return self._parent.execute(command, params)
  File "/home/max/.local/lib/python3.8/site-packages/selenium/webdriver/remote/webdriver.py", line 321, in execute
    self.error_handler.check_response(response)
  File "/home/max/.local/lib/python3.8/site-packages/selenium/webdriver/remote/errorhandler.py", line 242, in check_response
    raise exception_class(message, screen, stacktrace)
selenium.common.exceptions.StaleElementReferenceException: Message: stale element reference: element is not attached to the page document
  (Session info: headless chrome=84.0.4147.89)

ERROR    fs_past_stat_parser.py[LINE:93 2020-07-31 19:16][get_more_events] Button show more events not found url {url}
Traceback (most recent call last):
  File "/home/max/Projects/football-stat-scraper/stat_scraper/fs_past_stat_parser.py", line 91, in get_more_events
    more_event_btn.click()
  File "/home/max/.local/lib/python3.8/site-packages/selenium/webdriver/remote/webelement.py", line 80, in click
    self._execute(Command.CLICK_ELEMENT)
  File "/home/max/.local/lib/python3.8/site-packages/selenium/webdriver/remote/webelement.py", line 633, in _execute
    return self._parent.execute(command, params)
  File "/home/max/.local/lib/python3.8/site-packages/selenium/webdriver/remote/webdriver.py", line 321, in execute
    self.error_handler.check_response(response)
  File "/home/max/.local/lib/python3.8/site-packages/selenium/webdriver/remote/errorhandler.py", line 242, in check_response
    raise exception_class(message, screen, stacktrace)
selenium.common.exceptions.StaleElementReferenceException: Message: stale element reference: element is not attached to the page document
  (Session info: headless chrome=84.0.4147.89)

